@Test
public void should_propagate_AssertionError_from_nested_proxied_calls() {
    // the nested proxied call to isNotEmpty() throw an Assertion error that must be propagated to the caller.
    softly.then(emptyList()).first();
    // the nested proxied call to isNotEmpty() throw an Assertion error that must be propagated to the caller.
    softly.then(emptyList()).first(as(STRING));
    // the nested proxied call to isNotEmpty() throw an Assertion error that must be propagated to the caller.
    softly.then(emptyList()).last();
    // the nested proxied call to isNotEmpty() throw an Assertion error that must be propagated to the caller.
    softly.then(emptyList()).last(as(STRING));
    // the nested proxied call to isNotEmpty() throw an Assertion error that must be propagated to the caller.
    softly.then(emptyList()).element(1);
    // the nested proxied call to isNotEmpty() throw an Assertion error that must be propagated to the caller.
    softly.then(emptyList()).element(1, as(STRING));
    // nested proxied call to throwAssertionError when checking that is optional is present
    softly.then(Optional.empty()).contains("Foo");
    // nested proxied call to isNotNull
    softly.then((Predicate<String>) null).accepts("a", "b", "c");
    // nested proxied call to isCompleted
    softly.then(new CompletableFuture<String>()).isCompletedWithValue("done");
    // it must be caught by softly.assertAll()
    assertThat(softly.errorsCollected()).hasSize(9);
}
